<?xml version="1.0" ?>
<!-- =================================================================================== -->
<!-- |    This document was autogenerated by xacro from lion.xacro                     | -->
<!-- |    EDITING THIS FILE BY HAND IS NOT RECOMMENDED                                 | -->
<!-- =================================================================================== -->
<robot name="lion" xmlns:xacro="http://www.ros.org/wiki/xacro">
  <!--Robot Model*******************************************************************************************-->
  <link name="base_link">
    <inertial>
      <origin rpy="0 0 0" xyz="-0.000638750070817345 -0.00672058356158241 -0.00556735378698432"/>
      <mass value="4"/>
      <inertia ixx="0.024" ixy="-0.00" ixz="0.000245468989322163" iyy="0.0553119007901819" iyz="-0.00049300987765597" izz="0.0714019283806637"/>
    </inertial>
    <visual>
      <origin rpy="0 0 0" xyz="0 0 0"/>
      <geometry>
        <mesh filename="../meshes/base_link.STL"/>
      </geometry>
      <material name="">
        <color rgba="0.792156862745098 0.819607843137255 0.933333333333333 1"/>
      </material>
    </visual>
    <collision>
      <origin rpy="0 0 0" xyz="0 0 0"/>
      <geometry>
        <mesh filename="../meshes/base_link.STL"/>
      </geometry>
    </collision>
  </link>
  <link name="LegFR_hip">
    <inertial>
      <origin rpy="0 0 0" xyz="-0.0050797 -0.047183 4.172E-05"/>
      <mass value="0.39498"/>
      <inertia ixx="0.00036133" ixy="7.7674E-05" ixz="-5.1665E-07" iyy="0.00053159" iyz="-3.6439E-07" izz="0.00044943"/>
    </inertial>
    <visual>
      <origin rpy="0 0 0" xyz="0 0 0"/>
      <geometry>
        <mesh filename="../meshes/hip_Link.STL"/>
      </geometry>
      <material name="">
        <color rgba="0.79216 0.81961 0.93333 1"/>
      </material>
    </visual>
    <collision>
      <origin rpy="0 0 0" xyz="0 0 0"/>
      <geometry>
        <mesh filename="../meshes/hip_Link.STL"/>
      </geometry>
    </collision>
  </link>
  <joint name="JointFR_abad" type="revolute">
    <origin rpy="0.0 0.0 0 " xyz="0.2467 -0.09 0"/>
    <parent link="base_link"/>
    <child link="LegFR_hip"/>
    <axis xyz="1 0 0"/>
    <limit effort="55" lower="-1.0" upper="1.0" velocity="30"/>
  </joint>
  <link name="LegFR_thigh">
    <inertial>
      <origin rpy="0 0 0" xyz="-2.7705E-05 -0.089684 -0.23198"/>
      <mass value="0.5"/>
      <inertia ixx="0.0061823" ixy="3.3467E-07" ixz="2.1313E-06" iyy="0.0064396" iyz="-0.00019781" izz="0.00049549"/>
    </inertial>
    <visual>
      <origin rpy="0 0 0" xyz="0 0 0"/>
      <geometry>
        <mesh filename="../meshes/thigh_Link.STL"/>
      </geometry>
      <material name="">
        <color rgba="0.79216 0.81961 0.93333 1"/>
      </material>
    </visual>
    <collision>
      <origin rpy="0 0 0" xyz="0 0 0"/>
      <geometry>
        <mesh filename="../meshes/thigh_Link.STL"/>
      </geometry>
    </collision>
  </link>
  <joint name="JointFR_hip" type="revolute">
    <origin rpy="0 0.0 0" xyz="0 0 0"/>
    <parent link="LegFR_hip"/>
    <child link="LegFR_thigh"/>
    <axis xyz="0 1 0"/>
    <limit effort="55" lower="-3.0" upper="3.0" velocity="30"/>
  </joint>
  <link name="LegFR_shank">
    <inertial>
      <origin rpy="0 0 0" xyz="2.05E-06 -0.12517 -0.080832"/>
      <mass value="0.072713"/>
      <inertia ixx="0.00052861" ixy="-3.4646E-09" ixz="-2.7153E-09" iyy="0.00053174" iyz="2.8579E-05" izz="1.3053E-05"/>
    </inertial>
    <visual>
      <origin rpy="0 0 0" xyz="0 0 0"/>
      <geometry>
        <mesh filename="../meshes/shank_Link.STL"/>
      </geometry>
      <material name="">
        <color rgba="0.79216 0.81961 0.93333 1"/>
      </material>
    </visual>
    <collision>
      <origin rpy="0 0 0" xyz="0 0 0"/>
      <geometry>
        <mesh filename="../meshes/shank_Link.STL"/>
      </geometry>
    </collision>
  </link>
  <joint name="JointFR_knee" type="revolute">
    <origin rpy="0 0 0" xyz="0 0 -0.3"/>
    <parent link="LegFR_thigh"/>
    <child link="LegFR_shank"/>
    <axis xyz="0 1 0"/>
    <limit effort="55" lower="-3.0" upper="3.0" velocity="30"/>
  </joint>
  <link name="LegFR_foot">
    <inertial>
      <origin rpy="0 0 0" xyz="0.0002617 0.00017365 0.0085579"/>
      <mass value="0.03946"/>
      <inertia ixx="1.4527E-05" ixy="-8.5021E-08" ixz="-4.0103E-07" iyy="1.4601E-05" iyz="-2.6548E-07" izz="6.2338E-06"/>
    </inertial>
    <visual>
      <origin rpy="0 0 0" xyz="0 0 0"/>
      <geometry>
        <mesh filename="../meshes/foot_Link.STL"/>
      </geometry>
      <material name="">
        <color rgba="0.79216 0.81961 0.93333 1"/>
      </material>
    </visual>
    <collision>
      <origin rpy="0 0 0" xyz="0 0 0"/>
      <geometry>
        <mesh filename="../meshes/foot_Link.STL"/>
      </geometry>
    </collision>
  </link>
  <joint name="JointFR_foot" type="fixed">
    <origin rpy="0 0 0" xyz="0 -0.119 -0.3105"/>
    <parent link="LegFR_shank"/>
    <child link="LegFR_foot"/>
    <axis xyz="0 0 1"/>
    
  </joint>
  <link name="LegFL_hip">
    <inertial>
      <origin rpy="0 0 0" xyz="-0.0050797 -0.047183 4.172E-05"/>
      <mass value="0.39498"/>
      <inertia ixx="0.00036133" ixy="7.7674E-05" ixz="-5.1665E-07" iyy="0.00053159" iyz="-3.6439E-07" izz="0.00044943"/>
    </inertial>
    <visual>
      <origin rpy="0 0 0" xyz="0 0 0"/>
      <geometry>
        <mesh filename="../meshes/hip_Link.STL"/>
      </geometry>
      <material name="">
        <color rgba="0.79216 0.81961 0.93333 1"/>
      </material>
    </visual>
    <collision>
      <origin rpy="0 0 0" xyz="0 0 0"/>
      <geometry>
        <mesh filename="../meshes/hip_Link.STL"/>
      </geometry>
    </collision>
  </link>
  <joint name="JointFL_abad" type="revolute">
    <origin rpy="3.141592653589793 0.0 0 " xyz="0.2467 0.09 0"/>
    <parent link="base_link"/>
    <child link="LegFL_hip"/>
    <axis xyz="1 0 0"/>
    <limit effort="55" lower="-1.0" upper="1.0" velocity="30"/>
  </joint>
  <link name="LegFL_thigh">
    <inertial>
      <origin rpy="0 0 0" xyz="-2.7705E-05 -0.089684 -0.23198"/>
      <mass value="0.5"/>
      <inertia ixx="0.0061823" ixy="3.3467E-07" ixz="2.1313E-06" iyy="0.0064396" iyz="-0.00019781" izz="0.00049549"/>
    </inertial>
    <visual>
      <origin rpy="0 0 0" xyz="0 0 0"/>
      <geometry>
        <mesh filename="../meshes/thigh_Link.STL"/>
      </geometry>
      <material name="">
        <color rgba="0.79216 0.81961 0.93333 1"/>
      </material>
    </visual>
    <collision>
      <origin rpy="0 0 0" xyz="0 0 0"/>
      <geometry>
        <mesh filename="../meshes/thigh_Link.STL"/>
      </geometry>
    </collision>
  </link>
  <joint name="JointFL_hip" type="revolute">
    <origin rpy="0 3.141592653589793 0" xyz="0 0 0"/>
    <parent link="LegFL_hip"/>
    <child link="LegFL_thigh"/>
    <axis xyz="0 -1 0"/>
    <limit effort="55" lower="-3.0" upper="3.0" velocity="30"/>
  </joint>
  <link name="LegFL_shank">
    <inertial>
      <origin rpy="0 0 0" xyz="2.05E-06 -0.12517 -0.080832"/>
      <mass value="0.072713"/>
      <inertia ixx="0.00052861" ixy="-3.4646E-09" ixz="-2.7153E-09" iyy="0.00053174" iyz="2.8579E-05" izz="1.3053E-05"/>
    </inertial>
    <visual>
      <origin rpy="0 0 0" xyz="0 0 0"/>
      <geometry>
        <mesh filename="../meshes/shank_Link.STL"/>
      </geometry>
      <material name="">
        <color rgba="0.79216 0.81961 0.93333 1"/>
      </material>
    </visual>
    <collision>
      <origin rpy="0 0 0" xyz="0 0 0"/>
      <geometry>
        <mesh filename="../meshes/shank_Link.STL"/>
      </geometry>
    </collision>
  </link>
  <joint name="JointFL_knee" type="revolute">
    <origin rpy="0 0 0" xyz="0 0 -0.3"/>
    <parent link="LegFL_thigh"/>
    <child link="LegFL_shank"/>
    <axis xyz="0 -1 0"/>
    <limit effort="55" lower="-3.0" upper="3.0" velocity="30"/>
  </joint>
  <link name="LegFL_foot">
    <inertial>
      <origin rpy="0 0 0" xyz="0.0002617 0.00017365 0.0085579"/>
      <mass value="0.03946"/>
      <inertia ixx="1.4527E-05" ixy="-8.5021E-08" ixz="-4.0103E-07" iyy="1.4601E-05" iyz="-2.6548E-07" izz="6.2338E-06"/>
    </inertial>
    <visual>
      <origin rpy="0 0 0" xyz="0 0 0"/>
      <geometry>
        <mesh filename="../meshes/foot_Link.STL"/>
      </geometry>
      <material name="">
        <color rgba="0.79216 0.81961 0.93333 1"/>
      </material>
    </visual>
    <collision>
      <origin rpy="0 0 0" xyz="0 0 0"/>
      <geometry>
        <mesh filename="../meshes/foot_Link.STL"/>
      </geometry>
    </collision>
  </link>
  <joint name="JointFL_foot" type="fixed">
    <origin rpy="0 0 0" xyz="0 -0.119 -0.3105"/>
    <parent link="LegFL_shank"/>
    <child link="LegFL_foot"/>
    <axis xyz="0 0 1"/>
    
  </joint>
  <link name="LegHR_hip">
    <inertial>
      <origin rpy="0 0 0" xyz="-0.0050797 -0.047183 4.172E-05"/>
      <mass value="0.39498"/>
      <inertia ixx="0.00036133" ixy="7.7674E-05" ixz="-5.1665E-07" iyy="0.00053159" iyz="-3.6439E-07" izz="0.00044943"/>
    </inertial>
    <visual>
      <origin rpy="0 0 0" xyz="0 0 0"/>
      <geometry>
        <mesh filename="../meshes/hip_Link.STL"/>
      </geometry>
      <material name="">
        <color rgba="0.79216 0.81961 0.93333 1"/>
      </material>
    </visual>
    <collision>
      <origin rpy="0 0 0" xyz="0 0 0"/>
      <geometry>
        <mesh filename="../meshes/hip_Link.STL"/>
      </geometry>
    </collision>
  </link>
  <joint name="JointHR_abad" type="revolute">
    <origin rpy="0.0 3.141592653589793 0 " xyz="-0.2467 -0.09 0"/>
    <parent link="base_link"/>
    <child link="LegHR_hip"/>
    <axis xyz="-1 0 0"/>
    <limit effort="55" lower="-1.0" upper="1.0" velocity="30"/>
  </joint>
  <link name="LegHR_thigh">
    <inertial>
      <origin rpy="0 0 0" xyz="-2.7705E-05 -0.089684 -0.23198"/>
      <mass value="0.5"/>
      <inertia ixx="0.0061823" ixy="3.3467E-07" ixz="2.1313E-06" iyy="0.0064396" iyz="-0.00019781" izz="0.00049549"/>
    </inertial>
    <visual>
      <origin rpy="0 0 0" xyz="0 0 0"/>
      <geometry>
        <mesh filename="../meshes/thigh_Link.STL"/>
      </geometry>
      <material name="">
        <color rgba="0.79216 0.81961 0.93333 1"/>
      </material>
    </visual>
    <collision>
      <origin rpy="0 0 0" xyz="0 0 0"/>
      <geometry>
        <mesh filename="../meshes/thigh_Link.STL"/>
      </geometry>
    </collision>
  </link>
  <joint name="JointHR_hip" type="revolute">
    <origin rpy="0 3.141592653589793 0" xyz="0 0 0"/>
    <parent link="LegHR_hip"/>
    <child link="LegHR_thigh"/>
    <axis xyz="0 1 0"/>
    <limit effort="55" lower="-3.0" upper="3.0" velocity="30"/>
  </joint>
  <link name="LegHR_shank">
    <inertial>
      <origin rpy="0 0 0" xyz="2.05E-06 -0.12517 -0.080832"/>
      <mass value="0.072713"/>
      <inertia ixx="0.00052861" ixy="-3.4646E-09" ixz="-2.7153E-09" iyy="0.00053174" iyz="2.8579E-05" izz="1.3053E-05"/>
    </inertial>
    <visual>
      <origin rpy="0 0 0" xyz="0 0 0"/>
      <geometry>
        <mesh filename="../meshes/shank_Link.STL"/>
      </geometry>
      <material name="">
        <color rgba="0.79216 0.81961 0.93333 1"/>
      </material>
    </visual>
    <collision>
      <origin rpy="0 0 0" xyz="0 0 0"/>
      <geometry>
        <mesh filename="../meshes/shank_Link.STL"/>
      </geometry>
    </collision>
  </link>
  <joint name="JointHR_knee" type="revolute">
    <origin rpy="0 0 0" xyz="0 0 -0.3"/>
    <parent link="LegHR_thigh"/>
    <child link="LegHR_shank"/>
    <axis xyz="0 1 0"/>
    <limit effort="55" lower="-3.0" upper="3.0" velocity="30"/>
  </joint>
  <link name="LegHR_foot">
    <inertial>
      <origin rpy="0 0 0" xyz="0.0002617 0.00017365 0.0085579"/>
      <mass value="0.03946"/>
      <inertia ixx="1.4527E-05" ixy="-8.5021E-08" ixz="-4.0103E-07" iyy="1.4601E-05" iyz="-2.6548E-07" izz="6.2338E-06"/>
    </inertial>
    <visual>
      <origin rpy="0 0 0" xyz="0 0 0"/>
      <geometry>
        <mesh filename="../meshes/foot_Link.STL"/>
      </geometry>
      <material name="">
        <color rgba="0.79216 0.81961 0.93333 1"/>
      </material>
    </visual>
    <collision>
      <origin rpy="0 0 0" xyz="0 0 0"/>
      <geometry>
        <mesh filename="../meshes/foot_Link.STL"/>
      </geometry>
    </collision>
  </link>
  <joint name="JointHR_foot" type="fixed">
    <origin rpy="0 0 0" xyz="0 -0.119 -0.3105"/>
    <parent link="LegHR_shank"/>
    <child link="LegHR_foot"/>
    <axis xyz="0 0 1"/>
    
  </joint>
  <link name="LegHL_hip">
    <inertial>
      <origin rpy="0 0 0" xyz="-0.0050797 -0.047183 4.172E-05"/>
      <mass value="0.39498"/>
      <inertia ixx="0.00036133" ixy="7.7674E-05" ixz="-5.1665E-07" iyy="0.00053159" iyz="-3.6439E-07" izz="0.00044943"/>
    </inertial>
    <visual>
      <origin rpy="0 0 0" xyz="0 0 0"/>
      <geometry>
        <mesh filename="../meshes/hip_Link.STL"/>
      </geometry>
      <material name="">
        <color rgba="0.79216 0.81961 0.93333 1"/>
      </material>
    </visual>
    <collision>
      <origin rpy="0 0 0" xyz="0 0 0"/>
      <geometry>
        <mesh filename="../meshes/hip_Link.STL"/>
      </geometry>
    </collision>
  </link>
  <joint name="JointHL_abad" type="revolute">
    <origin rpy="3.141592653589793 3.141592653589793 0 " xyz="-0.2467 0.09 0"/>
    <parent link="base_link"/>
    <child link="LegHL_hip"/>
    <axis xyz="-1 0 0"/>
    <limit effort="55" lower="-1.0" upper="1.0" velocity="30"/>
  </joint>
  <link name="LegHL_thigh">
    <inertial>
      <origin rpy="0 0 0" xyz="-2.7705E-05 -0.089684 -0.23198"/>
      <mass value="0.5"/>
      <inertia ixx="0.0061823" ixy="3.3467E-07" ixz="2.1313E-06" iyy="0.0064396" iyz="-0.00019781" izz="0.00049549"/>
    </inertial>
    <visual>
      <origin rpy="0 0 0" xyz="0 0 0"/>
      <geometry>
        <mesh filename="../meshes/thigh_Link.STL"/>
      </geometry>
      <material name="">
        <color rgba="0.79216 0.81961 0.93333 1"/>
      </material>
    </visual>
    <collision>
      <origin rpy="0 0 0" xyz="0 0 0"/>
      <geometry>
        <mesh filename="../meshes/thigh_Link.STL"/>
      </geometry>
    </collision>
  </link>
  <joint name="JointHL_hip" type="revolute">
    <origin rpy="0 6.283185307179586 0" xyz="0 0 0"/>
    <parent link="LegHL_hip"/>
    <child link="LegHL_thigh"/>
    <axis xyz="0 -1 0"/>
    <limit effort="55" lower="-3.0" upper="3.0" velocity="30"/>
  </joint>
  <link name="LegHL_shank">
    <inertial>
      <origin rpy="0 0 0" xyz="2.05E-06 -0.12517 -0.080832"/>
      <mass value="0.072713"/>
      <inertia ixx="0.00052861" ixy="-3.4646E-09" ixz="-2.7153E-09" iyy="0.00053174" iyz="2.8579E-05" izz="1.3053E-05"/>
    </inertial>
    <visual>
      <origin rpy="0 0 0" xyz="0 0 0"/>
      <geometry>
        <mesh filename="../meshes/shank_Link.STL"/>
      </geometry>
      <material name="">
        <color rgba="0.79216 0.81961 0.93333 1"/>
      </material>
    </visual>
    <collision>
      <origin rpy="0 0 0" xyz="0 0 0"/>
      <geometry>
        <mesh filename="../meshes/shank_Link.STL"/>
      </geometry>
    </collision>
  </link>
  <joint name="JointHL_knee" type="revolute">
    <origin rpy="0 0 0" xyz="0 0 -0.3"/>
    <parent link="LegHL_thigh"/>
    <child link="LegHL_shank"/>
    <axis xyz="0 -1 0"/>
    <limit effort="55" lower="-3.0" upper="3.0" velocity="30"/>
  </joint>
  <link name="LegHL_foot">
    <inertial>
      <origin rpy="0 0 0" xyz="0.0002617 0.00017365 0.0085579"/>
      <mass value="0.03946"/>
      <inertia ixx="1.4527E-05" ixy="-8.5021E-08" ixz="-4.0103E-07" iyy="1.4601E-05" iyz="-2.6548E-07" izz="6.2338E-06"/>
    </inertial>
    <visual>
      <origin rpy="0 0 0" xyz="0 0 0"/>
      <geometry>
        <mesh filename="../meshes/foot_Link.STL"/>
      </geometry>
      <material name="">
        <color rgba="0.79216 0.81961 0.93333 1"/>
      </material>
    </visual>
    <collision>
      <origin rpy="0 0 0" xyz="0 0 0"/>
      <geometry>
        <mesh filename="../meshes/foot_Link.STL"/>
      </geometry>
    </collision>
  </link>
  <joint name="JointHL_foot" type="fixed">
    <origin rpy="0 0 0" xyz="0 -0.119 -0.3105"/>
    <parent link="LegHL_shank"/>
    <child link="LegHL_foot"/>
    <axis xyz="0 0 1"/>
    
  </joint>
</robot>

